{"uuid": "1e3b164a-bd35-48de-95c0-f67f88d58081", "children": ["ecc325fa-9520-4159-bb60-3027c3f31298", "70461c39-31a9-4f95-bf72-8c326d2503be"], "befores": [{"name": "db", "status": "broken", "statusDetails": {"message": "mysql.connector.errors.InterfaceError: 2003: Can't connect to MySQL server on 'localhost:3306' (10061 No connection could be made because the target machine actively refused it)\n", "trace": "  File \"c:\\users\\vkarpenko\\pycharmprojects\\python_training\\env\\lib\\site-packages\\pluggy\\callers.py\", line 187, in _multicall\n    res = hook_impl.function(*args)\n  File \"c:\\users\\vkarpenko\\pycharmprojects\\python_training\\env\\lib\\site-packages\\_pytest\\fixtures.py\", line 1126, in pytest_fixture_setup\n    result = call_fixture_func(fixturefunc, request, kwargs)\n  File \"c:\\users\\vkarpenko\\pycharmprojects\\python_training\\env\\lib\\site-packages\\_pytest\\fixtures.py\", line 932, in call_fixture_func\n    fixture_result = fixturefunc(**kwargs)\n  File \"C:\\Users\\vkarpenko\\PycharmProjects\\python_training\\conftest.py\", line 42, in db\n    dbfixture = DbFixture(host=db_config['host'], name=db_config['name'], user=db_config['user'], password=db_config['password'])\n  File \"C:\\Users\\vkarpenko\\PycharmProjects\\python_training\\fixture\\db.py\", line 14, in __init__\n    self.connection = mysql.connector.connect(host=host, database=name, user=user, password=password)\n  File \"c:\\users\\vkarpenko\\pycharmprojects\\python_training\\env\\lib\\site-packages\\mysql\\connector\\__init__.py\", line 278, in connect\n    return MySQLConnection(*args, **kwargs)\n  File \"c:\\users\\vkarpenko\\pycharmprojects\\python_training\\env\\lib\\site-packages\\mysql\\connector\\connection.py\", line 108, in __init__\n    self.connect(**kwargs)\n  File \"c:\\users\\vkarpenko\\pycharmprojects\\python_training\\env\\lib\\site-packages\\mysql\\connector\\abstracts.py\", line 1003, in connect\n    self._open_connection()\n  File \"c:\\users\\vkarpenko\\pycharmprojects\\python_training\\env\\lib\\site-packages\\mysql\\connector\\connection.py\", line 351, in _open_connection\n    self._socket.open_connection()\n  File \"c:\\users\\vkarpenko\\pycharmprojects\\python_training\\env\\lib\\site-packages\\mysql\\connector\\network.py\", line 610, in open_connection\n    errno=2003, values=(self.get_address(), _strioerror(err)))\n"}, "start": 1613632599259, "stop": 1613632600286}], "start": 1613632599259, "stop": 1613632600633}